Workbook

Sheet Info
C5: In this excel sheet you need to fill in your burial history models
C6: You need to provide depths and ages for every layer in your stratigraphic section (including the surface).
C7: You do not need to provide data for the layer of your actual sample because that information comes through the Cronus input sheet
C8: If you have several layers constrained in a stratigraphic section, please use a separate line for every constrained layer, while using the same sample name. Also, order your layers from top to bottom.
C10: sample
C11: depths (m) | E11: depth of layer below surface
C12: depth uncerts (m)
C13: age (ka) | E13: age of layer
C14: age uncerts (ka)

Sheet 10Be_Model1
A1: Sample | B1: depths (m) | C1: depth uncerts (m) | D1: age (ka) | E1: age uncerts (ka) (Difference in 2signma) | F1: Notes
A2: SC-14-S4 | B2: 0 | C2: 0 | D2: 0.2 | E2: 0.05 | AL2: SC-14-S2 | AM2: 0 | AN2: 0 | AO2: 0.2 | AP2: 0.05
A3: SC-14-S3 | B3: 0 | C3: 0 | D3: 0.2 | E3: 0.05 | AL3: SC-14-S2-real | AM3: 0.53 | AN3: 0 | AO3: 1.87 | AP3: 0.06
A4: SC-14-S3 | B4: =AVERAGE(AM3:AM4) -> 0.64 | C4: =AVERAGE(AN3:AN4) -> 0 | D4: =AVERAGE(AO3:AO4) -> 1.84 | E4: 0.06 | F4: *Averaged out inverse ages which will throw up an error in postpro (can't have younger below older duh) | AL4: SC-14-S2-real | AM4: 0.75 | AN4: 0 | AO4: 1.81 | AP4: 0.07
A5: SC-14-S3 | B5: 0.9 | C5: 0 | D5: 2.06 | E5: 0.07 | AL5: SC-14-S2 | AM5: 0.9 | AN5: 0 | AO5: 2.06 | AP5: 0.07
A6: SC-14-S2 | B6: 0 | C6: 0 | D6: 0.2 | E6: 0.05 | AL6: SC-14-S2 | AM6: 1.45 | AN6: 0 | AO6: 2.59 | AP6: 0.12
A7: SC-14-S2 | B7: =B4 -> 0.64 | C7: =C4 -> 0 | D7: =D4 -> 1.84 | E7: =E4 -> 0.06 | AL7: SC14S1 | AM7: 2.2 | AN7: 0 | AO7: 3.34 | AP7: 0.03
A8: SC-14-S2 | B8: 0.9 | C8: 0 | D8: 2.06 | E8: 0.07 | AL8: =AL7 -> SC14S1 | AM8: 2.45 | AN8: 0 | AO8: 3.58 | AP8: 0.05
A9: SC-14-S2 | B9: 1.45 | C9: 0 | D9: 2.59 | E9: 0.12 | F9: *Averaged out inverse ages which will throw up an error in postpro (can't have younger below older duh) | AL9: SC14S2 averaged | AM9: 0.64 | AN9: 0 | AO9: 1.84 | AP9: 0.06
A10: SC-15-S2 | B10: 0 | C10: 0 | D10: 0.54 | E10: 0.05
A11: SC-15-S2 | B11: 0.5 | C11: 0 | D11: 1.31 | E11: 0.03
A12: SC-15-S2 | B12: 1.2 | C12: 0 | D12: 2.45 | E12: 0.08
A13: SC-15-S2 | B13: 1.9 | C13: 0 | D13: 3.63 | E13: 0.04
A14: SC-15-S2 | B14: 2.5 | C14: 0 | D14: 4.56 | E14: 0.03
A15: SC-15-S2 | B15: 2.7 | C15: 0 | D15: 4.61 | E15: 0.03
A16: SC-15-S1 | B16: 0 | C16: 0 | D16: 0.54 | E16: 0.05 | Q16: 14S3 | Z16: 14S3
A17: SC-15-S1 | B17: 0.5 | C17: 0 | D17: 1.31 | E17: 0.03 | Q17: =0.9841*0.91+1.1704 -> 2.065931 | Z17: =1.0736*0.95+1.0439 -> 2.06382 | AA17: =0.9318*0.91+1.2347 -> 2.082638 | AD17: =0.9699*0.905+1.2 -> 2.0777595
A18: SC-15-S1 | B18: 1.2 | C18: 0 | D18: 2.45 | E18: 0.08
A19: SC-15-S1 | B19: 1.9 | C19: 0 | D19: 3.63 | E19: 0.04
A20: SC-15-S1 | B20: 2.5 | C20: 0 | D20: 4.56 | E20: 0.03
A21: SC-15-S1 | B21: 2.7 | C21: 0 | D21: 4.61 | E21: 0.03
A22: SC-15-S1 | B22: =AVERAGE(B23:B24) -> 4.275 | C22: 0 | D22: =AVERAGE(D23:D24) -> 8.45 | E22: 0.05 | F22: Disconformity. Postpro is encountering an error because the depth change and age change is so rapid below. Thus I averaged the two ages out.
A23: SC-15-S1-real | B23: 4.25 | C23: 0 | D23: 7.3 | E23: 0.04
A24: SC-15-S1-real | B24: 4.3 | C24: 0 | D24: 9.6 | E24: 0.05
A25: SC-16-S4 | B25: =14.32-14.32 -> 0 | C25: 0 | D25: 3.41 | E25: 0.05
A26: SC-16-S4 | B26: =14.32-13.06 -> 1.26 | C26: 0 | D26: 3.98 | E26: 0.04
A27: SC-16-S3 | B27: =14.32-14.32 -> 0 | C27: 0 | D27: 3.41 | E27: 0.05
A28: SC-16-S3 | B28: =14.32-13.06 -> 1.26 | C28: 0 | D28: =0.001*AVERAGE(4296,4566) -> 4.431 | E28: =0.001*(4566-4298)/2 -> 0.134
A29: SC-16-S3 | B29: =14.32-9.85 -> 4.47 | C29: 0 | D29: =0.001*AVERAGE(8772,9234) -> 9.003 | E29: =0.001*(9234-8772)/2 -> 0.231
A30: SC-16-S3 | B30: =14.32-7 -> 7.32 | C30: 0 | D30: =0.001*AVERAGE(10756,11160) -> 10.958 | E30: =0.001*(11160-10756)/2 -> 0.202
Q35: 15S2 | W35: 15S2
Q36: =1.5493*2.95+0.5852 -> 5.155635 | W36: =1.5786*2.95+0.5415 -> 5.19837
Q37: 15S1 | R37: Assuming constant erosion and a disconformity between 7.30 and 9.64 ka | W37: 15S1 | AD37: 15S1
Q38: =1.5493*4.6+0.5852 +(9.64-7.3) -> 10.05198 | R38: Asumming same deposition rate but adding a 2.34 ka disconformity, i.e., I am adding this this missing time | W38: =1.5786*4.6+0.5415 -> 7.80306 | AD38: =46*4.6-188.2 -> 23.4 | AE38: Not possible so it must be disconformity
AM39: =14.32-14.32 -> 0 | AN39: 0 | AO39: 3.41 | AP39: 0.05
AM40: =14.32-13.06 -> 1.26 | AN40: 0 | AO40: =0.001*AVERAGE(4296,4566) -> 4.431 | AP40: =0.001*(4566-4298)/2 -> 0.134
AM41: =14.32-9.85 -> 4.47 | AN41: 0 | AO41: =0.001*AVERAGE(8772,9234) -> 9.003 | AP41: =0.001*(9234-8772)/2 -> 0.231
AM42: =14.32-7 -> 7.32 | AN42: 0 | AO42: =0.001*AVERAGE(10756,11160) -> 10.958 | AP42: =0.001*(11160-10756)/2 -> 0.202
AM43: =14.32-5.9 -> 8.42 | AN43: 0 | AO43: =0.001*AVERAGE(13659,13896) -> 13.7775
R56: SC16S3 | Z56: SC16S3
...

Sheet 10Be_Model2
A1: Sample | B1: depths (m) | C1: depth uncerts (m) | D1: age (ka) | E1: age uncerts (ka)
A2: EL-919-1 | B2: 0 | C2: 0 | D2: 71.1 | E2: 7.5
A3: Sf-919-11 | B3: 0 | C3: 0 | D3: 10.8 | E3: 1.2
A4: Sf-919-12 | B4: 0 | C4: 0 | D4: 10.8 | E4: 1.2
A5: Sf-919-12 | B5: 5 | C5: 1 | D5: 28 | E5: 2
A6: Sf-919-12 | B6: 5.5 | C6: 1 | D6: 49 | E6: 4
A7: Sf-919-14 | B7: 0 | C7: 0 | D7: 10.8 | E7: 1.2
A8: Sf-919-15 | B8: 0 | C8: 0 | D8: 10.8 | E8: 1.2

Sheet 36Cl_Model1
A1: Sample | B1: depths (m) | C1: depth uncerts (m) | D1: age (ka) | E1: age uncerts (ka)

Sheet 36Cl_Model2
A1: Sample | B1: depths (m) | C1: depth uncerts (m) | D1: age (ka) | E1: age uncerts (ka)

Sheet 14C_Model1
A1: ='10Be_Model1'!A1 -> Sample | B1: ='10Be_Model1'!B1 -> depths (m) | C1: ='10Be_Model1'!C1 -> depth uncerts (m) | D1: ='10Be_Model1'!D1 -> age (ka) | E1: ='10Be_Model1'!E1 -> age uncerts (ka) (Difference in 2signma) | F1: ='10Be_Model1'!F1 -> Notes
A2: ='10Be_Model1'!A2 -> SC-14-S4 | B2: ='10Be_Model1'!B2 -> 0 | C2: ='10Be_Model1'!C2 -> 0 | D2: ='10Be_Model1'!D2 -> 0.2 | E2: ='10Be_Model1'!E2 -> 0.05
A3: ='10Be_Model1'!A3 -> SC-14-S3 | B3: ='10Be_Model1'!B3 -> 0 | C3: ='10Be_Model1'!C3 -> 0 | D3: ='10Be_Model1'!D3 -> 0.2 | E3: ='10Be_Model1'!E3 -> 0.05
A4: ='10Be_Model1'!A4 -> SC-14-S3 | B4: ='10Be_Model1'!B4 -> 0.64 | C4: ='10Be_Model1'!C4 -> 0 | D4: ='10Be_Model1'!D4 -> 1.84 | E4: ='10Be_Model1'!E4 -> 0.06 | F4: ='10Be_Model1'!F4 -> *Averaged out inverse ages which will throw up an error in postpro (can't have younger below older duh)
A5: ='10Be_Model1'!A5 -> SC-14-S3 | B5: ='10Be_Model1'!B5 -> 0.9 | C5: ='10Be_Model1'!C5 -> 0 | D5: ='10Be_Model1'!D5 -> 2.06 | E5: ='10Be_Model1'!E5 -> 0.07
A6: ='10Be_Model1'!A6 -> SC-14-S2 | B6: ='10Be_Model1'!B6 -> 0 | C6: ='10Be_Model1'!C6 -> 0 | D6: ='10Be_Model1'!D6 -> 0.2 | E6: ='10Be_Model1'!E6 -> 0.05
A7: ='10Be_Model1'!A7 -> SC-14-S2 | B7: ='10Be_Model1'!B7 -> 0.64 | C7: ='10Be_Model1'!C7 -> 0 | D7: ='10Be_Model1'!D7 -> 1.84 | E7: ='10Be_Model1'!E7 -> 0.06
A8: ='10Be_Model1'!A8 -> SC-14-S2 | B8: ='10Be_Model1'!B8 -> 0.9 | C8: ='10Be_Model1'!C8 -> 0 | D8: ='10Be_Model1'!D8 -> 2.06 | E8: ='10Be_Model1'!E8 -> 0.07
A9: ='10Be_Model1'!A9 -> SC-14-S2 | B9: ='10Be_Model1'!B9 -> 1.45 | C9: ='10Be_Model1'!C9 -> 0 | D9: ='10Be_Model1'!D9 -> 2.59 | E9: ='10Be_Model1'!E9 -> 0.12 | F9: ='10Be_Model1'!F9 -> *Averaged out inverse ages which will throw up an error in postpro (can't have younger below older duh)
A10: ='10Be_Model1'!A10 -> SC-15-S2 | B10: ='10Be_Model1'!B10 -> 0 | C10: ='10Be_Model1'!C10 -> 0 | D10: ='10Be_Model1'!D10 -> 0.54 | E10: ='10Be_Model1'!E10 -> 0.05
A11: ='10Be_Model1'!A11 -> SC-15-S2 | B11: ='10Be_Model1'!B11 -> 0.5 | C11: ='10Be_Model1'!C11 -> 0 | D11: ='10Be_Model1'!D11 -> 1.31 | E11: ='10Be_Model1'!E11 -> 0.03
A12: ='10Be_Model1'!A12 -> SC-15-S2 | B12: ='10Be_Model1'!B12 -> 1.2 | C12: ='10Be_Model1'!C12 -> 0 | D12: ='10Be_Model1'!D12 -> 2.45 | E12: ='10Be_Model1'!E12 -> 0.08
A13: ='10Be_Model1'!A13 -> SC-15-S2 | B13: ='10Be_Model1'!B13 -> 1.9 | C13: ='10Be_Model1'!C13 -> 0 | D13: ='10Be_Model1'!D13 -> 3.63 | E13: ='10Be_Model1'!E13 -> 0.04
A14: ='10Be_Model1'!A14 -> SC-15-S2 | B14: ='10Be_Model1'!B14 -> 2.5 | C14: ='10Be_Model1'!C14 -> 0 | D14: ='10Be_Model1'!D14 -> 4.56 | E14: ='10Be_Model1'!E14 -> 0.03
A15: ='10Be_Model1'!A15 -> SC-15-S2 | B15: ='10Be_Model1'!B15 -> 2.7 | C15: ='10Be_Model1'!C15 -> 0 | D15: ='10Be_Model1'!D15 -> 4.61 | E15: ='10Be_Model1'!E15 -> 0.03
A16: ='10Be_Model1'!A16 -> SC-15-S1 | B16: ='10Be_Model1'!B16 -> 0 | C16: ='10Be_Model1'!C16 -> 0 | D16: ='10Be_Model1'!D16 -> 0.54 | E16: ='10Be_Model1'!E16 -> 0.05
A17: ='10Be_Model1'!A17 -> SC-15-S1 | B17: ='10Be_Model1'!B17 -> 0.5 | C17: ='10Be_Model1'!C17 -> 0 | D17: ='10Be_Model1'!D17 -> 1.31 | E17: ='10Be_Model1'!E17 -> 0.03
A18: ='10Be_Model1'!A18 -> SC-15-S1 | B18: ='10Be_Model1'!B18 -> 1.2 | C18: ='10Be_Model1'!C18 -> 0 | D18: ='10Be_Model1'!D18 -> 2.45 | E18: ='10Be_Model1'!E18 -> 0.08
A19: ='10Be_Model1'!A19 -> SC-15-S1 | B19: ='10Be_Model1'!B19 -> 1.9 | C19: ='10Be_Model1'!C19 -> 0 | D19: ='10Be_Model1'!D19 -> 3.63 | E19: ='10Be_Model1'!E19 -> 0.04
A20: ='10Be_Model1'!A20 -> SC-15-S1 | B20: ='10Be_Model1'!B20 -> 2.5 | C20: ='10Be_Model1'!C20 -> 0 | D20: ='10Be_Model1'!D20 -> 4.56 | E20: ='10Be_Model1'!E20 -> 0.03
A21: ='10Be_Model1'!A21 -> SC-15-S1 | B21: ='10Be_Model1'!B21 -> 2.7 | C21: ='10Be_Model1'!C21 -> 0 | D21: ='10Be_Model1'!D21 -> 4.61 | E21: ='10Be_Model1'!E21 -> 0.03
A22: ='10Be_Model1'!A22 -> SC-15-S1 | B22: ='10Be_Model1'!B22 -> 4.275 | C22: ='10Be_Model1'!C22 -> 0 | D22: ='10Be_Model1'!D22 -> 8.45 | E22: ='10Be_Model1'!E22 -> 0.05 | F22: ='10Be_Model1'!F22 -> Disconformity. Postpro is encountering an error because the depth change and age change is so rapid below. Thus I averaged the two ages out.
A23: ='10Be_Model1'!A23 -> SC-15-S1-real | B23: ='10Be_Model1'!B23 -> 4.25 | C23: ='10Be_Model1'!C23 -> 0 | D23: ='10Be_Model1'!D23 -> 7.3 | E23: ='10Be_Model1'!E23 -> 0.04
A24: ='10Be_Model1'!A24 -> SC-15-S1-real | B24: ='10Be_Model1'!B24 -> 4.3 | C24: ='10Be_Model1'!C24 -> 0 | D24: ='10Be_Model1'!D24 -> 9.6 | E24: ='10Be_Model1'!E24 -> 0.05
A25: ='10Be_Model1'!A25 -> SC-16-S4 | B25: ='10Be_Model1'!B25 -> 0 | C25: ='10Be_Model1'!C25 -> 0 | D25: ='10Be_Model1'!D25 -> 3.41 | E25: ='10Be_Model1'!E25 -> 0.05
A26: ='10Be_Model1'!A26 -> SC-16-S4 | B26: ='10Be_Model1'!B26 -> 1.26 | C26: ='10Be_Model1'!C26 -> 0 | D26: ='10Be_Model1'!D26 -> 3.98 | E26: ='10Be_Model1'!E26 -> 0.04
A27: ='10Be_Model1'!A27 -> SC-16-S3 | B27: ='10Be_Model1'!B27 -> 0 | C27: ='10Be_Model1'!C27 -> 0 | D27: ='10Be_Model1'!D27 -> 3.41 | E27: ='10Be_Model1'!E27 -> 0.05
A28: ='10Be_Model1'!A28 -> SC-16-S3 | B28: ='10Be_Model1'!B28 -> 1.26 | C28: ='10Be_Model1'!C28 -> 0 | D28: ='10Be_Model1'!D28 -> 4.431 | E28: ='10Be_Model1'!E28 -> 0.134
A29: ='10Be_Model1'!A29 -> SC-16-S3 | B29: ='10Be_Model1'!B29 -> 4.47 | C29: ='10Be_Model1'!C29 -> 0 | D29: ='10Be_Model1'!D29 -> 9.003 | E29: ='10Be_Model1'!E29 -> 0.231
A30: ='10Be_Model1'!A30 -> SC-16-S3 | B30: ='10Be_Model1'!B30 -> 7.32 | C30: ='10Be_Model1'!C30 -> 0 | D30: ='10Be_Model1'!D30 -> 10.958 | E30: ='10Be_Model1'!E30 -> 0.202
